<?xml version="1.0"?>

<robot xmlns="http://drake.mit.edu"
       xmlns:xsi="http://www.w3.org/2001/XMLSchema-instance"
       xsi:schemaLocation="http://drake.mit.edu ../../doc/drakeURDF.xsd" name="five_link">
  <material name="black">
    <color rgba="0 0 0 1" />
  </material>
  <material name="MITred">
    <color rgba=".6 .2 .2 1" />
  </material>
  
  <!-- first define all the links   -->
  <!-- ============================================================================== -->

  <link name="base">
	<inertial>
      <mass value="0"/>
      <inertia ixx="0.2125" ixy="-0.005" ixz="0.0225" iyy="0.205" iyz="0.045" izz="0.0125"/>
      <origin rpy="0 0 0" xyz="0 0 0"/>
    </inertial>
  </link>

  <link name="y_prismatic">
	<inertial>
      <mass value="0.01"/>
      <inertia ixx="0.2125" ixy="-0.005" ixz="0.0225" iyy="0.205" iyz="0.045" izz="0.0125"/>
      <origin rpy="0 0 0" xyz="0 0 0"/>
    </inertial>
  </link>
  
  <joint name="y_to_world" type="prismatic">
    <parent link="base"/>
    <child link="y_prismatic"/>
    <axis xyz="1 0 0"/>
    <!-- <limit effort="0.0" lower="1" upper="-1" velocity="1000.0"/> -->
    <origin rpy="0 0 0" xyz="0 0 0"/>
  </joint>
		
  <link name="x_prismatic">
	<inertial>
      <mass value="0.01"/>
      <inertia ixx="0.2125" ixy="-0.005" ixz="0.0225" iyy="0.205" iyz="0.045" izz="0.0125"/>
      <origin rpy="0 0 0" xyz="0 0 0"/>
    </inertial>
  </link>
	
  <joint name="x_to_y" type="prismatic">
    <parent link="y_prismatic"/>
    <child link="x_prismatic"/>
    <axis xyz="0 0 1"/>
    <!-- <limit effort="0.0" lower="1" upper="-1" velocity="1000.0"/> -->
    <origin rpy="0 0 0" xyz="0 0 -1.4"/>
  </joint>
  
  <joint name="ls_to_x" type="continuous">
    <parent link="x_prismatic"/>
    <child link="lower_stance"/>
    <axis xyz="0 1 0"/>
    <origin rpy="0 0 0" xyz="0 0 1.4"/>
  </joint>

  
  <link name="lower_stance">
    <inertial> 
      <origin xyz="0 1 -.5" rpy="0 0 0" />
      <mass value="10" />
      <inertia ixx=".083" ixy="0" ixz="0" iyy="1" iyz="0" izz="0.083"/> 
    </inertial>
    <visual>
      <origin xyz="0 1 -.5" rpy="0 0 0" />
      <geometry>
        <cylinder length="1" radius=".01" />
      </geometry>
      <color rgba="1 1 0 1" />
    </visual>
    <collision>
      <origin xyz="0 1 -.5" rpy="0 0 0" />
      <geometry>
        <cylinder length="1" radius=".01" />
      </geometry>
      <!-- <contact_coefficients mu="0" kp="5000" kd="5000"/> -->
    </collision>
  </link>

  <link name="upper_stance">
    <inertial> 
      <origin xyz="0 -1 -.5" rpy="0 0 0" />
      <mass value="10" />
      <inertia ixx=".083" ixy="0" ixz="0" iyy="1" iyz="0" izz="0.083"/> 
    </inertial>
    <collision>
      <origin xyz="0 -1 -.5" rpy="0 0 0" />
      <geometry>
        <cylinder length="1" radius=".01" />
      </geometry>
    </collision>
    <visual>
      <origin xyz="0 -1 -.5" rpy="0 0 0" />
      <geometry>
        <cylinder length="1" radius=".01" />
      </geometry>
      <color rgba="1 1 0 1" />
    </visual> 
  </link>
  
  <link name="torso">
    <inertial> 
      <origin xyz="0 0 -.25" rpy="0 0 0" />
      <mass value="10" />
      <inertia ixx="1" ixy="0" ixz="0" iyy="1" iyz="0" izz="0.083"/> 
    </inertial>
    <collision>
      <origin xyz="0 0 -.25" rpy="0 0 0" />
      <geometry>
        <cylinder length=".5" radius=".01" />
      </geometry>
    </collision>
    <visual>
      <origin xyz="0 0 -.25" rpy="0 0 0" />
      <geometry>
        <cylinder length=".5" radius=".01" />
      </geometry>
      <color rgba="1 1 0 1" />
    </visual>    
  </link>

  <link name="lower_swing">
    <inertial> 
      <origin xyz="0 1 -.5" rpy="0 0 0" />
      <mass value="10" />
      <inertia ixx="1" ixy="0" ixz="0" iyy="1" iyz="0" izz="0.083"/> 
    </inertial>
    <visual>
      <origin xyz="0 0 -.5" rpy="0 0 0" />
      <geometry>
        <cylinder length="1" radius=".01" />
      </geometry>
      <color rgba="1 1 0 1" />
    </visual>
    <collision>
      <origin xyz="0 0 -.5" rpy="0 0 0" />
      <geometry>
        <cylinder length="1" radius=".01" />
        <!-- <contact_coefficients mu="0" kp="50000" kd="500000" /> -->
      </geometry>
    </collision>
  </link>

  <link name="upper_swing">
    <inertial> 
      <origin xyz="0 0 -.5" rpy="0 0 0" />
      <mass value="10" />
      <inertia ixx="1" ixy="0" ixz="0" iyy="1" iyz="0" izz="0.083"/> 
    </inertial>
    <collision>
      <origin xyz="0 0 -.5" rpy="0 0 0" />
      <geometry>
        <cylinder length="1" radius=".01" />
      </geometry>
    </collision>
    <visual>
      <origin xyz="0 0 -.5" rpy="0 0 0" />
      <geometry>
        <cylinder length="1" radius=".01" />
      </geometry>
      <color rgba="1 1 0 1" />
    </visual> 
  </link>
  

  <!-- now all the joints and motors   -->
  <!-- ============================================================================== -->

  
  <!-- <joint name="base_joint" type="continuous"> -->
  <!--   <parent link="base"/> -->
  <!--   <child link="lower_stance" /> -->
  <!--   <axis xyz="0 1 0" /> -->
  <!--   <dynamics damping="0.1" /> -->
  <!-- </joint> -->
  
  <joint name="stance_knee" type="continuous">
    <parent link="lower_stance"/>
    <origin xyz="0 0 -1" />
    <child link="upper_stance" />
    <axis xyz="0 1 0" />
    <dynamics damping="0.1" />
  </joint>
  <transmission type="SimpleTransmission" name="stance_trans">
    <actuator name="stance_knee" />
    <joint name="stance_knee" />
    <mechanicalReduction>1</mechanicalReduction>
  </transmission>

  
  <joint name="torso_joint" type="continuous">
    <parent link="upper_stance"/>
    <origin xyz="0 0 -1" />
    <child link="torso" />
    <axis xyz="0 1 0" />
    <dynamics damping="0.1" />
  </joint>
  <transmission type="SimpleTransmission" name="torso_trans">
    <actuator name="torso_joint" />
    <joint name="torso_joint" />
    <mechanicalReduction>1</mechanicalReduction>
  </transmission>

  <joint name="swing_stance" type="continuous">
    <parent link="upper_stance"/>
    <origin xyz="0 0 -1" />
    <child link="upper_swing" />
    <axis xyz="0 1 0" />
    <dynamics damping="0.1" />
  </joint>
  <transmission type="SimpleTransmission" name="swing_stance_trans">
    <actuator name="swing_stance" />
    <joint name="swing_stance" />
    <mechanicalReduction>1</mechanicalReduction>
  </transmission>

  
  <joint name="swing_knee" type="continuous">
    <parent link="upper_swing"/>
    <origin xyz="0 0 -1" />
    <child link="lower_swing" />
    <axis xyz="0 1 0" />
    <dynamics damping="0.1" />
  </joint>
  <transmission type="SimpleTransmission" name="swing_trans">
    <actuator name="swing_knee" />
    <joint name="swing_knee" />
    <mechanicalReduction>1</mechanicalReduction>
  </transmission>
    
</robot>
